<?xml version="1.0" encoding="utf-8"?>
<!-- This URDF was automatically created by SolidWorks to URDF Exporter! Originally created by Stephen Brawner (brawner@gmail.com) 
     Commit Version: 1.6.0-1-g15f4949  Build Version: 1.6.7594.29634
     For more information, please see http://wiki.ros.org/sw_urdf_exporter -->
<robot
  name="mobile_robot">
  <link
    name="robotbody">
    <inertial>
      <origin
        xyz="0.00401986265500357 -3.38053883261469E-07 0.139113696127112"
        rpy="0 0 0" />
      <mass
        value="179.829612357079" />
      <inertia
        ixx="8.00890289620713"
        ixy="-0.000179509794248011"
        ixz="-0.299284451335136"
        iyy="16.5906319304822"
        iyz="4.97520809226732E-06"
        izz="20.5250031833796" />
    </inertial>
    <visual>
      <origin
        xyz="0 0 0"
        rpy="0 0 0" />
      <geometry>
        <mesh
          filename="package://mobile_robot/meshes/robotbody.STL" />
      </geometry>
      <material
        name="">
        <color
          rgba="1 1 1 1" />
      </material>
    </visual>
    <collision>
      <origin
        xyz="0 0 0"
        rpy="0 0 0" />
      <geometry>
        <mesh
          filename="package://mobile_robot/meshes/robotbody.STL" />
      </geometry>
    </collision>
  </link>
  <link
    name="rightlink1">
    <inertial>
      <origin
        xyz="-3.83175091656085E-08 0.095483335975443 -4.46796599717914E-10"
        rpy="0 0 0" />
      <mass
        value="7.62715538668072" />
      <inertia
        ixx="0.0518990119646793"
        ixy="-5.2496981510775E-09"
        ixz="8.86898894268719E-09"
        iyy="0.057713859419024"
        iyz="8.20946127408135E-09"
        izz="0.051899050380724" />
    </inertial>
    <visual>
      <origin
        xyz="0 0 0"
        rpy="0 0 0" />
      <geometry>
        <mesh
          filename="package://mobile_robot/meshes/rightlink1.STL" />
      </geometry>
      <material
        name="">
        <color
          rgba="0.250980392156863 0.250980392156863 0.250980392156863 1" />
      </material>
    </visual>
    <collision>
      <origin
        xyz="0 0 0"
        rpy="0 0 0" />
      <geometry>
        <mesh
          filename="package://mobile_robot/meshes/rightlink1.STL" />
      </geometry>
    </collision>
  </link>
  <joint
    name="rightjoint1"
    type="continuous">
    <origin
      xyz="0.36483 -0.345 -0.2"
      rpy="0 0 0" />
    <parent
      link="robotbody" />
    <child
      link="rightlink1" />
    <axis
      xyz="0 1 0" />
    <limit
      effort="1"
      velocity="1" />
  </joint>
  <link
    name="rightlink2">
    <inertial>
      <origin
        xyz="-3.79036528275201E-08 0.0954833359754431 5.63420177179808E-09"
        rpy="0 0 0" />
      <mass
        value="7.62715538668074" />
      <inertia
        ixx="0.0518990048667419"
        ixy="-3.88165945706751E-09"
        ixz="1.4436996314533E-08"
        iyy="0.057713861454517"
        iyz="8.93796985939286E-09"
        izz="0.0518990357976471" />
    </inertial>
    <visual>
      <origin
        xyz="0 0 0"
        rpy="0 0 0" />
      <geometry>
        <mesh
          filename="package://mobile_robot/meshes/rightlink2.STL" />
      </geometry>
      <material
        name="">
        <color
          rgba="0.250980392156863 0.250980392156863 0.250980392156863 1" />
      </material>
    </visual>
    <collision>
      <origin
        xyz="0 0 0"
        rpy="0 0 0" />
      <geometry>
        <mesh
          filename="package://mobile_robot/meshes/rightlink2.STL" />
      </geometry>
    </collision>
  </link>
  <joint
    name="rightjoint2"
    type="continuous">
    <origin
      xyz="-0.37017 -0.345 -0.2"
      rpy="0 0 0" />
    <parent
      link="robotbody" />
    <child
      link="rightlink2" />
    <axis
      xyz="0 1 0" />
    <limit
      effort="1"
      velocity="1" />
  </joint>
  <link
    name="leftlink1">
    <inertial>
      <origin
        xyz="1.35252116728601E-08 -0.095483335975443 3.58538670974795E-08"
        rpy="0 0 0" />
      <mass
        value="7.62715538668061" />
      <inertia
        ixx="0.0518990515877837"
        ixy="5.91886764828209E-09"
        ixz="-5.5526390684369E-09"
        iyy="0.057713859419038"
        iyz="-7.74090377170621E-09"
        izz="0.0518990107576337" />
    </inertial>
    <visual>
      <origin
        xyz="0 0 0"
        rpy="0 0 0" />
      <geometry>
        <mesh
          filename="package://mobile_robot/meshes/leftlink1.STL" />
      </geometry>
      <material
        name="">
        <color
          rgba="0.250980392156863 0.250980392156863 0.250980392156863 1" />
      </material>
    </visual>
    <collision>
      <origin
        xyz="0 0 0"
        rpy="0 0 0" />
      <geometry>
        <mesh
          filename="package://mobile_robot/meshes/leftlink1.STL" />
      </geometry>
    </collision>
  </link>
  <joint
    name="leftjoint1"
    type="continuous">
    <origin
      xyz="0.36483 0.345 -0.2"
      rpy="0 0 0" />
    <parent
      link="robotbody" />
    <child
      link="leftlink1" />
    <axis
      xyz="0 1 0" />
    <limit
      effort="1"
      velocity="1" />
  </joint>
  <link
    name="leftlink2">
    <inertial>
      <origin
        xyz="1.95456919538373E-08 -0.095483335975443 3.29605379656428E-08"
        rpy="0 0 0" />
      <mass
        value="7.62715538668075" />
      <inertia
        ixx="0.0518990457065327"
        ixy="4.48475294235125E-09"
        ixz="-1.22001408662112E-08"
        iyy="0.0577138599424099"
        iyz="-8.65110259669706E-09"
        izz="0.0518990111369708" />
    </inertial>
    <visual>
      <origin
        xyz="0 0 0"
        rpy="0 0 0" />
      <geometry>
        <mesh
          filename="package://mobile_robot/meshes/leftlink2.STL" />
      </geometry>
      <material
        name="">
        <color
          rgba="0.250980392156863 0.250980392156863 0.250980392156863 1" />
      </material>
    </visual>
    <collision>
      <origin
        xyz="0 0 0"
        rpy="0 0 0" />
      <geometry>
        <mesh
          filename="package://mobile_robot/meshes/leftlink2.STL" />
      </geometry>
    </collision>
  </link>
  <joint
    name="leftjoint2"
    type="continuous">
    <origin
      xyz="-0.37017 0.345 -0.2"
      rpy="0 0 0" />
    <parent
      link="robotbody" />
    <child
      link="leftlink2" />
    <axis
      xyz="0 1 0" />
    <limit
      effort="1"
      velocity="1" />
  </joint>
</robot>